Workbook

Sheet comm_nodist_plants
A1: id | B1: database | C1: id_comm | D1: id_study | E1: id_study_ori | F1: citation | G1: study | H1: site | I1: plot | J1: id_comm_source | K1: exact_lat | L1: exact_long | M1: age | N1: age_ori | O1: study_year | P1: temp_persp_class2 | Q1: stage | R1: study_common_taxon | S1: organism_threshold | T1: metric | U1: metric_source | V1: aggregated_data | W1: sampling_method | X1: sampling_effort_within | Y1: sampling_effort_among | Z1: n_comm | AA1: n_comm_available | AB1: effort_ori | AC1: historic_impact | AD1: predisturbances | AE1: disturbance1_age | AF1: disturbance2 | AG1: n_disturbances | AH1: current_impact | AI1: notes | AJ1: priority | AK1: country | AL1: study_common_taxon_clean | AM1: study_common_taxon_strgroup | AN1: disturbance1_age_clean | AO1: disturbance2_clean | AP1: predisturbances_clean | AQ1: current_impact_clean | AR1: postdisturbance | AS1: restoration | AT1: protection | AU1: use | AV1: recovering_cond | AW1: coord_accuracy | AX1: taxon_level | AY1: richness_study | AZ1: richness | BA1: abund | BB1: shannon | BC1: PD | BD1: SR | BE1: error_class
A2: PR_Baeten et al. 2010_Baeten Belgium vegetation recovery_p1_NA | B2: PR | C2: Baeten et al. 2010_Baeten Belgium vegetation recovery_p1_NA | D2: PR_Baeten et al. 2010_Baeten Belgium vegetation recovery | E2: PR_Baeten et al. 2010_Baeten Belgium vegetation recovery | F2: Baeten et al. 2010 | G2: Baeten Belgium vegetation recovery | H2: p1 | I2: NA | J2: p1 | K2: 51123051 | L2: 3221795 | M2: 2 | N2: 2 | O2: 2006 | P2: exact | Q2: recovering | R2: woody and herbaceous | S2: presence | T2: abundance | U2: diameter stem base for woody and percent cover for herbaceous. Joint results are in percentaje cover | V2: no | W2: fixed plots/quadrats | X2: 1 | Y2: NA | Z2: 1 | AA2: 71 | AB2: 1 | AC2: deforestation and reforestation phases. 4.4% remaining forest cover | AD2: NA | AE2: productive grassland | AF2: bought for passive restoration | AG2: 1 | AH2: NA | AI2: Plots are aggregated but we do not know how | AJ2: NA | AK2: Belgium | AL2: vascular plants | AM2: mix | AN2: animal farming | AO2: protection | AP2: NA | AQ2: NA | AR2: none | AS2: 0 | AT2: 1 | AU2: none | AV2: protection | AW2: community | AX2: species | AY2: 92 | AZ2: 13 | BA2: 36.14 | BB2: 1.8357899e+16 | BC2: 741458122 | BD2: 10 | BE2: 0.13043478260869565
A3: PR_Baeten et al. 2010_Baeten Belgium vegetation recovery_p10_NA | B3: PR | C3: Baeten et al. 2010_Baeten Belgium vegetation recovery_p10_NA | D3: PR_Baeten et al. 2010_Baeten Belgium vegetation recovery | E3: PR_Baeten et al. 2010_Baeten Belgium vegetation recovery | F3: Baeten et al. 2010 | G3: Baeten Belgium vegetation recovery | H3: p10 | I3: NA | J3: p10 | K3: 51119913 | L3: 3235139 | M3: 1 | N3: 1 | O3: 2006 | P3: exact | Q3: recovering | R3: woody and herbaceous | S3: presence | T3: abundance | U3: diameter stem base for woody and percent cover for herbaceous. Joint results are in percentaje cover | V3: no | W3: fixed plots/quadrats | X3: 1 | Y3: NA | Z3: 1 | AA3: 71 | AB3: 1 | AC3: deforestation and reforestation phases. 4.4% remaining forest cover | AD3: NA | AE3: productive grassland | AF3: bought for passive restoration | AG3: 1 | AH3: NA | AI3: Plots are aggregated but we do not know how | AJ3: NA | AK3: Belgium | AL3: vascular plants | AM3: mix | AN3: animal farming | AO3: protection | AP3: NA | AQ3: NA | AR3: none | AS3: 0 | AT3: 1 | AU3: none | AV3: protection | AW3: community | AX3: species | AY3: 92 | AZ3: 8 | BA3: 98.97 | BB3: 2.0782963e+15 | BC3: 814298105 | BD3: 8 | BE3: 0.13043478260869565
A4: PR_Baeten et al. 2010_Baeten Belgium vegetation recovery_p11_NA | B4: PR | C4: Baeten et al. 2010_Baeten Belgium vegetation recovery_p11_NA | D4: PR_Baeten et al. 2010_Baeten Belgium vegetation recovery | E4: PR_Baeten et al. 2010_Baeten Belgium vegetation recovery | F4: Baeten et al. 2010 | G4: Baeten Belgium vegetation recovery | H4: p11 | I4: NA | J4: p11 | K4: 51120067 | L4: 3234797 | M4: 1 | N4: 1 | O4: 2006 | P4: exact | Q4: recovering | R4: woody and herbaceous | S4: presence | T4: abundance | U4: diameter stem base for woody and percent cover for herbaceous. Joint results are in percentaje cover | V4: no | W4: fixed plots/quadrats | X4: 1 | Y4: NA | Z4: 1 | AA4: 71 | AB4: 1 | AC4: deforestation and reforestation phases. 4.4% remaining forest cover | AD4: NA | AE4: productive grassland | AF4: bought for passive restoration | AG4: 1 | AH4: NA | AI4: Plots are aggregated but we do not know how | AJ4: NA | AK4: Belgium | AL4: vascular plants | AM4: mix | AN4: animal farming | AO4: protection | AP4: NA | AQ4: NA | AR4: none | AS4: 0 | AT4: 1 | AU4: none | AV4: protection | AW4: community | AX4: species | AY4: 92 | AZ4: 7 | BA4: 100.01 | BB4: 2.3031238e+15 | BC4: 668569884 | BD4: 7 | BE4: 0.13043478260869565
A5: PR_Baeten et al. 2010_Baeten Belgium vegetation recovery_p12_NA | B5: PR | C5: Baeten et al. 2010_Baeten Belgium vegetation recovery_p12_NA | D5: PR_Baeten et al. 2010_Baeten Belgium vegetation recovery | E5: PR_Baeten et al. 2010_Baeten Belgium vegetation recovery | F5: Baeten et al. 2010 | G5: Baeten Belgium vegetation recovery | H5: p12 | I5: NA | J5: p12 | K5: 51120175 | L5: 3234512 | M5: 1 | N5: 1 | O5: 2006 | P5: exact | Q5: recovering | R5: woody and herbaceous | S5: presence | T5: abundance | U5: diameter stem base for woody and percent cover for herbaceous. Joint results are in percentaje cover | V5: no | W5: fixed plots/quadrats | X5: 1 | Y5: NA | Z5: 1 | AA5: 71 | AB5: 1 | AC5: deforestation and reforestation phases. 4.4% remaining forest cover | AD5: NA | AE5: productive grassland | AF5: bought for passive restoration | AG5: 1 | AH5: NA | AI5: Plots are aggregated but we do not know how | AJ5: NA | AK5: Belgium | AL5: vascular plants | AM5: mix | AN5: animal farming | AO5: protection | AP5: NA | AQ5: NA | AR5: none | AS5: 0 | AT5: 1 | AU5: none | AV5: protection | AW5: community | AX5: species | AY5: 92 | AZ5: 9 | BA5: 100 | BB5: 2.1487901e+15 | BC5: 8.2336197e+15 | BD5: 9 | BE5: 0.13043478260869565
A6: PR_Baeten et al. 2010_Baeten Belgium vegetation recovery_p13_NA | B6: PR | C6: Baeten et al. 2010_Baeten Belgium vegetation recovery_p13_NA | D6: PR_Baeten et al. 2010_Baeten Belgium vegetation recovery | E6: PR_Baeten et al. 2010_Baeten Belgium vegetation recovery | F6: Baeten et al. 2010 | G6: Baeten Belgium vegetation recovery | H6: p13 | I6: NA | J6: p13 | K6: 51116535 | L6: 3242265 | M6: 5 | N6: 5 | O6: 2006 | P6: exact | Q6: recovering | R6: woody and herbaceous | S6: presence | T6: abundance | U6: diameter stem base for woody and percent cover for herbaceous. Joint results are in percentaje cover | V6: no | W6: fixed plots/quadrats | X6: 1 | Y6: NA | Z6: 1 | AA6: 71 | AB6: 1 | AC6: deforestation and reforestation phases. 4.4% remaining forest cover | AD6: NA | AE6: intensive maize crop | AF6: bought for passive restoration | AG6: 1 | AH6: NA | AI6: Plots are aggregated but we do not know how | AJ6: NA | AK6: Belgium | AL6: vascular plants | AM6: mix | AN6: cultivation | AO6: protection | AP6: NA | AQ6: NA | AR6: none | AS6: 0 | AT6: 1 | AU6: none | AV6: protection | AW6: community | AX6: species | AY6: 92 | AZ6: 11 | BA6: 3.28 | BB6: 1.9742284e+16 | BC6: 8.4288083e+15 | BD6: 9 | BE6: 0.13043478260869565
A7: PR_Baeten et al. 2010_Baeten Belgium vegetation recovery_p14_NA | B7: PR | C7: Baeten et al. 2010_Baeten Belgium vegetation recovery_p14_NA | D7: PR_Baeten et al. 2010_Baeten Belgium vegetation recovery | E7: PR_Baeten et al. 2010_Baeten Belgium vegetation recovery | F7: Baeten et al. 2010 | G7: Baeten Belgium vegetation recovery | H7: p14 | I7: NA | J7: p14 | K7: 51116813 | L7: 3242824 | M7: 5 | N7: 5 | O7: 2006 | P7: exact | Q7: recovering | R7: woody and herbaceous | S7: presence | T7: abundance | U7: diameter stem base for woody and percent cover for herbaceous. Joint results are in percentaje cover | V7: no | W7: fixed plots/quadrats | X7: 1 | Y7: NA | Z7: 1 | AA7: 71 | AB7: 1 | AC7: deforestation and reforestation phases. 4.4% remaining forest cover | AD7: NA | AE7: intensive maize crop | AF7: bought for passive restoration | AG7: 1 | AH7: NA | AI7: Plots are aggregated but we do not know how | AJ7: NA | AK7: Belgium | AL7: vascular plants | AM7: mix | AN7: cultivation | AO7: protection | AP7: NA | AQ7: NA | AR7: none | AS7: 0 | AT7: 1 | AU7: none | AV7: protection | AW7: community | AX7: species | AY7: 92 | AZ7: 7 | BA7: 80.1 | BB7: 1.139218e+15 | BC7: 636054854 | BD7: 6 | BE7: 0.13043478260869565
A8: PR_Baeten et al. 2010_Baeten Belgium vegetation recovery_p15_NA | B8: PR | C8: Baeten et al. 2010_Baeten Belgium vegetation recovery_p15_NA | D8: PR_Baeten et al. 2010_Baeten Belgium vegetation recovery | E8: PR_Baeten et al. 2010_Baeten Belgium vegetation recovery | F8: Baeten et al. 2010 | G8: Baeten Belgium vegetation recovery | H8: p15 | I8: NA | J8: p15 | K8: 51117118 | L8: 3243383 | M8: 5 | N8: 5 | O8: 2006 | P8: exact | Q8: recovering | R8: woody and herbaceous | S8: presence | T8: abundance | U8: diameter stem base for woody and percent cover for herbaceous. Joint results are in percentaje cover | V8: no | W8: fixed plots/quadrats | X8: 1 | Y8: NA | Z8: 1 | AA8: 71 | AB8: 1 | AC8: deforestation and reforestation phases. 4.4% remaining forest cover | AD8: NA | AE8: intensive maize crop | AF8: bought for passive restoration | AG8: 1 | AH8: NA | AI8: Plots are aggregated but we do not know how | AJ8: NA | AK8: Belgium | AL8: vascular plants | AM8: mix | AN8: cultivation | AO8: protection | AP8: NA | AQ8: NA | AR8: none | AS8: 0 | AT8: 1 | AU8: none | AV8: protection | AW8: community | AX8: species | AY8: 92 | AZ8: 8 | BA8: 5.56 | BB8: 1.7977107e+16 | BC8: 646698456 | BD8: 6 | BE8: 0.13043478260869565
A9: PR_Baeten et al. 2010_Baeten Belgium vegetation recovery_p16_NA | B9: PR | C9: Baeten et al. 2010_Baeten Belgium vegetation recovery_p16_NA | D9: PR_Baeten et al. 2010_Baeten Belgium vegetation recovery | E9: PR_Baeten et al. 2010_Baeten Belgium vegetation recovery | F9: Baeten et al. 2010 | G9: Baeten Belgium vegetation recovery | H9: p16 | I9: NA | J9: p16 | K9: 51116424 | L9: 3243893 | M9: 3 | N9: 3 | O9: 2006 | P9: exact | Q9: recovering | R9: woody and herbaceous | S9: presence | T9: abundance | U9: diameter stem base for woody and percent cover for herbaceous. Joint results are in percentaje cover | V9: no | W9: fixed plots/quadrats | X9: 1 | Y9: NA | Z9: 1 | AA9: 71 | AB9: 1 | AC9: deforestation and reforestation phases. 4.4% remaining forest cover | AD9: NA | AE9: intensive maize crop | AF9: bought for passive restoration | AG9: 1 | AH9: NA | AI9: Plots are aggregated but we do not know how | AJ9: NA | AK9: Belgium | AL9: vascular plants | AM9: mix | AN9: cultivation | AO9: protection | AP9: NA | AQ9: NA | AR9: none | AS9: 0 | AT9: 1 | AU9: none | AV9: protection | AW9: community | AX9: species | AY9: 92 | AZ9: 16 | BA9: 53.69 | BB9: 2.8691852e+16 | BC9: 954461839 | BD9: 13 | BE9: 0.13043478260869565
A10: PR_Baeten et al. 2010_Baeten Belgium vegetation recovery_p17_NA | B10: PR | C10: Baeten et al. 2010_Baeten Belgium vegetation recovery_p17_NA | D10: PR_Baeten et al. 2010_Baeten Belgium vegetation recovery | E10: PR_Baeten et al. 2010_Baeten Belgium vegetation recovery | F10: Baeten et al. 2010 | G10: Baeten Belgium vegetation recovery | H10: p17 | I10: NA | J10: p17 | K10: 51116353 | L10: 3243536 | M10: 3 | N10: 3 | O10: 2006 | P10: exact | Q10: recovering | R10: woody and herbaceous | S10: presence | T10: abundance | U10: diameter stem base for woody and percent cover for herbaceous. Joint results are in percentaje cover | V10: no | W10: fixed plots/quadrats | X10: 1 | Y10: NA | Z10: 1 | AA10: 71 | AB10: 1 | AC10: deforestation and reforestation phases. 4.4% remaining forest cover | AD10: NA | AE10: intensive maize crop | AF10: bought for passive restoration | AG10: 1 | AH10: NA | AI10: Plots are aggregated but we do not know how | AJ10: NA | AK10: Belgium | AL10: vascular plants | AM10: mix | AN10: cultivation | AO10: protection | AP10: NA | AQ10: NA | AR10: none | AS10: 0 | AT10: 1 | AU10: none | AV10: protection | AW10: community | AX10: species | AY10: 92 | AZ10: 13 | BA10: 26.1 | BB10: 2.962306e+16 | BC10: 6100192 | BD10: 10 | BE10: 0.13043478260869565
A11: PR_Baeten et al. 2010_Baeten Belgium vegetation recovery_p18_NA | B11: PR | C11: Baeten et al. 2010_Baeten Belgium vegetation recovery_p18_NA | D11: PR_Baeten et al. 2010_Baeten Belgium vegetation recovery | E11: PR_Baeten et al. 2010_Baeten Belgium vegetation recovery | F11: Baeten et al. 2010 | G11: Baeten Belgium vegetation recovery | H11: p18 | I11: NA | J11: p18 | K11: 51116237 | L11: 3243192 | M11: 3 | N11: 3 | O11: 2006 | P11: exact | Q11: recovering | R11: woody and herbaceous | S11: presence | T11: abundance | U11: diameter stem base for woody and percent cover for herbaceous. Joint results are in percentaje cover | V11: no | W11: fixed plots/quadrats | X11: 1 | Y11: NA | Z11: 1 | AA11: 71 | AB11: 1 | AC11: deforestation and reforestation phases. 4.4% remaining forest cover | AD11: NA | AE11: intensive maize crop | AF11: bought for passive restoration | AG11: 1 | AH11: NA | AI11: Plots are aggregated but we do not know how | AJ11: NA | AK11: Belgium | AL11: vascular plants | AM11: mix | AN11: cultivation | AO11: protection | AP11: NA | AQ11: NA | AR11: none | AS11: 0 | AT11: 1 | AU11: none | AV11: protection | AW11: community | AX11: species | AY11: 92 | AZ11: 21 | BA11: 78.2 | BB11: 2.922291e+16 | BC11: 1073556722 | BD11: 18 | BE11: 0.13043478260869565
A12: PR_Baeten et al. 2010_Baeten Belgium vegetation recovery_p19_NA | B12: PR | C12: Baeten et al. 2010_Baeten Belgium vegetation recovery_p19_NA | D12: PR_Baeten et al. 2010_Baeten Belgium vegetation recovery | E12: PR_Baeten et al. 2010_Baeten Belgium vegetation recovery | F12: Baeten et al. 2010 | G12: Baeten Belgium vegetation recovery | H12: p19 | I12: NA | J12: p19 | K12: 51116112 | L12: 3242863 | M12: 3 | N12: 3 | O12: 2006 | P12: exact | Q12: recovering | R12: woody and herbaceous | S12: presence | T12: abundance | U12: diameter stem base for woody and percent cover for herbaceous. Joint results are in percentaje cover | V12: no | W12: fixed plots/quadrats | X12: 1 | Y12: NA | Z12: 1 | AA12: 71 | AB12: 1 | AC12: deforestation and reforestation phases. 4.4% remaining forest cover | AD12: NA | AE12: intensive maize crop | AF12: bought for passive restoration | AG12: 1 | AH12: NA | AI12: Plots are aggregated but we do not know how | AJ12: NA | AK12: Belgium | AL12: vascular plants | AM12: mix | AN12: cultivation | AO12: protection | AP12: NA | AQ12: NA | AR12: none | AS12: 0 | AT12: 1 | AU12: none | AV12: protection | AW12: community | AX12: species | AY12: 92 | AZ12: 20 | BA12: 35745 | BB12: 2.9379187e+16 | BC12: 796903057 | BD12: 14 | BE12: 0.13043478260869565
A13: PR_Baeten et al. 2010_Baeten Belgium vegetation recovery_p2_NA | B13: PR | C13: Baeten et al. 2010_Baeten Belgium vegetation recovery_p2_NA | D13: PR_Baeten et al. 2010_Baeten Belgium vegetation recovery | E13: PR_Baeten et al. 2010_Baeten Belgium vegetation recovery | F13: Baeten et al. 2010 | G13: Baeten Belgium vegetation recovery | H13: p2 | I13: NA | J13: p2 | K13: 51122716 | L13: 3222979 | M13: 2 | N13: 2 | O13: 2006 | P13: exact | Q13: recovering | R13: woody and herbaceous | S13: presence | T13: abundance | U13: diameter stem base for woody and percent cover for herbaceous. Joint results are in percentaje cover | V13: no | W13: fixed plots/quadrats | X13: 1 | Y13: NA | Z13: 1 | AA13: 71 | AB13: 1 | AC13: deforestation and reforestation phases. 4.4% remaining forest cover | AD13: NA | AE13: productive grassland | AF13: bought for passive restoration | AG13: 1 | AH13: NA | AI13: Plots are aggregated but we do not know how | AJ13: NA | AK13: Belgium | AL13: vascular plants | AM13: mix | AN13: animal farming | AO13: protection | AP13: NA | AQ13: NA | AR13: none | AS13: 0 | AT13: 1 | AU13: none | AV13: protection | AW13: community | AX13: species | AY13: 92 | AZ13: 16 | BA13: 27.36 | BB13: 2.4598976e+15 | BC13: 8193504458 | BD13: 13 | BE13: 0.13043478260869565
A14: PR_Baeten et al. 2010_Baeten Belgium vegetation recovery_p20_NA | B14: PR | C14: Baeten et al. 2010_Baeten Belgium vegetation recovery_p20_NA | D14: PR_Baeten et al. 2010_Baeten Belgium vegetation recovery | E14: PR_Baeten et al. 2010_Baeten Belgium vegetation recovery | F14: Baeten et al. 2010 | G14: Baeten Belgium vegetation recovery | H14: p20 | I14: NA | J14: p20 | K14: 51116262 | L14: 3244078 | M14: 3 | N14: 3 | O14: 2006 | P14: exact | Q14: recovering | R14: woody and herbaceous | S14: presence | T14: abundance | U14: diameter stem base for woody and percent cover for herbaceous. Joint results are in percentaje cover | V14: no | W14: fixed plots/quadrats | X14: 1 | Y14: NA | Z14: 1 | AA14: 71 | AB14: 1 | AC14: deforestation and reforestation phases. 4.4% remaining forest cover | AD14: NA | AE14: intensive maize crop | AF14: bought for passive restoration | AG14: 1 | AH14: NA | AI14: Plots are aggregated but we do not know how | AJ14: NA | AK14: Belgium | AL14: vascular plants | AM14: mix | AN14: cultivation | AO14: protection | AP14: NA | AQ14: NA | AR14: none | AS14: 0 | AT14: 1 | AU14: none | AV14: protection | AW14: community | AX14: species | AY14: 92 | AZ14: 23 | BA14: 35.1 | BB14: 3.2735606e+16 | BC14: 12442029638 | BD14: 18 | BE14: 0.13043478260869565
A15: PR_Baeten et al. 2010_Baeten Belgium vegetation recovery_p21_NA | B15: PR | C15: Baeten et al. 2010_Baeten Belgium vegetation recovery_p21_NA | D15: PR_Baeten et al. 2010_Baeten Belgium vegetation recovery | E15: PR_Baeten et al. 2010_Baeten Belgium vegetation recovery | F15: Baeten et al. 2010 | G15: Baeten Belgium vegetation recovery | H15: p21 | I15: NA | J15: p21 | K15: 51116128 | L15: 3243749 | M15: 3 | N15: 3 | O15: 2006 | P15: exact | Q15: recovering | R15: woody and herbaceous | S15: presence | T15: abundance | U15: diameter stem base for woody and percent cover for herbaceous. Joint results are in percentaje cover | V15: no | W15: fixed plots/quadrats | X15: 1 | Y15: NA | Z15: 1 | AA15: 71 | AB15: 1 | AC15: deforestation and reforestation phases. 4.4% remaining forest cover | AD15: NA | AE15: intensive maize crop | AF15: bought for passive restoration | AG15: 1 | AH15: NA | AI15: Plots are aggregated but we do not know how | AJ15: NA | AK15: Belgium | AL15: vascular plants | AM15: mix | AN15: cultivation | AO15: protection | AP15: NA | AQ15: NA | AR15: none | AS15: 0 | AT15: 1 | AU15: none | AV15: protection | AW15: community | AX15: species | AY15: 92 | AZ15: 18 | BA15: 76.35 | BB15: 2.5785492e+15 | BC15: 8219206352 | BD15: 14 | BE15: 0.13043478260869565
A16: PR_Baeten et al. 2010_Baeten Belgium vegetation recovery_p22_NA | B16: PR | C16: Baeten et al. 2010_Baeten Belgium vegetation recovery_p22_NA | D16: PR_Baeten et al. 2010_Baeten Belgium vegetation recovery | E16: PR_Baeten et al. 2010_Baeten Belgium vegetation recovery | F16: Baeten et al. 2010 | G16: Baeten Belgium vegetation recovery | H16: p22 | I16: NA | J16: p22 | K16: 51115985 | L16: 3243391 | M16: 3 | N16: 3 | O16: 2006 | P16: exact | Q16: recovering | R16: woody and herbaceous | S16: presence | T16: abundance | U16: diameter stem base for woody and percent cover for herbaceous. Joint results are in percentaje cover | V16: no | W16: fixed plots/quadrats | X16: 1 | Y16: NA | Z16: 1 | AA16: 71 | AB16: 1 | AC16: deforestation and reforestation phases. 4.4% remaining forest cover | AD16: NA | AE16: intensive maize crop | AF16: bought for passive restoration | AG16: 1 | AH16: NA | AI16: Plots are aggregated but we do not know how | AJ16: NA | AK16: Belgium | AL16: vascular plants | AM16: mix | AN16: cultivation | AO16: protection | AP16: NA | AQ16: NA | AR16: none | AS16: 0 | AT16: 1 | AU16: none | AV16: protection | AW16: community | AX16: species | AY16: 92 | AZ16: 19 | BA16: 46.13 | BB16: 2.6772412e+16 | BC16: 8.5350145e+15 | BD16: 14 | BE16: 0.13043478260869565
A17: PR_Baeten et al. 2010_Baeten Belgium vegetation recovery_p23_NA | B17: PR | C17: Baeten et al. 2010_Baeten Belgium vegetation recovery_p23_NA | D17: PR_Baeten et al. 2010_Baeten Belgium vegetation recovery | E17: PR_Baeten et al. 2010_Baeten Belgium vegetation recovery | F17: Baeten et al. 2010 | G17: Baeten Belgium vegetation recovery | H17: p23 | I17: NA | J17: p23 | K17: 51115868 | L17: 3243062 | M17: 3 | N17: 3 | O17: 2006 | P17: exact | Q17: recovering | R17: woody and herbaceous | S17: presence | T17: abundance | U17: diameter stem base for woody and percent cover for herbaceous. Joint results are in percentaje cover | V17: no | W17: fixed plots/quadrats | X17: 1 | Y17: NA | Z17: 1 | AA17: 71 | AB17: 1 | AC17: deforestation and reforestation phases. 4.4% remaining forest cover | AD17: NA | AE17: intensive maize crop | AF17: bought for passive restoration | AG17: 1 | AH17: NA | AI17: Plots are aggregated but we do not know how | AJ17: NA | AK17: Belgium | AL17: vascular plants | AM17: mix | AN17: cultivation | AO17: protection | AP17: NA | AQ17: NA | AR17: none | AS17: 0 | AT17: 1 | AU17: none | AV17: protection | AW17: community | AX17: species | AY17: 92 | AZ17: 18 | BA17: 66.37 | BB17: 3.0301174e+15 | BC17: 1108285626 | BD17: 15 | BE17: 0.13043478260869565
A18: PR_Baeten et al. 2010_Baeten Belgium vegetation recovery_p24_NA | B18: PR | C18: Baeten et al. 2010_Baeten Belgium vegetation recovery_p24_NA | D18: PR_Baeten et al. 2010_Baeten Belgium vegetation recovery | E18: PR_Baeten et al. 2010_Baeten Belgium vegetation recovery | F18: Baeten et al. 2010 | G18: Baeten Belgium vegetation recovery | H18: p24 | I18: NA | J18: p24 | K18: 51115716 | L18: 3242704 | M18: 3 | N18: 3 | O18: 2006 | P18: exact | Q18: recovering | R18: woody and herbaceous | S18: presence | T18: abundance | U18: diameter stem base for woody and percent cover for herbaceous. Joint results are in percentaje cover | V18: no | W18: fixed plots/quadrats | X18: 1 | Y18: NA | Z18: 1 | AA18: 71 | AB18: 1 | AC18: deforestation and reforestation phases. 4.4% remaining forest cover | AD18: NA | AE18: intensive maize crop | AF18: bought for passive restoration | AG18: 1 | AH18: NA | AI18: Plots are aggregated but we do not know how | AJ18: NA | AK18: Belgium | AL18: vascular plants | AM18: mix | AN18: cultivation | AO18: protection | AP18: NA | AQ18: NA | AR18: none | AS18: 0 | AT18: 1 | AU18: none | AV18: protection | AW18: community | AX18: species | AY18: 92 | AZ18: 13 | BA18: 96.48 | BB18: 1.0165493e+16 | BC18: 1158551181 | BD18: 12 | BE18: 0.13043478260869565
A19: PR_Baeten et al. 2010_Baeten Belgium vegetation recovery_p25_NA | B19: PR | C19: Baeten et al. 2010_Baeten Belgium vegetation recovery_p25_NA | D19: PR_Baeten et al. 2010_Baeten Belgium vegetation recovery | E19: PR_Baeten et al. 2010_Baeten Belgium vegetation recovery | F19: Baeten et al. 2010 | G19: Baeten Belgium vegetation recovery | H19: p25 | I19: NA | J19: p25 | K19: 51115582 | L19: 324236 | M19: 3 | N19: 3 | O19: 2006 | P19: exact | Q19: recovering | R19: woody and herbaceous | S19: presence | T19: abundance | U19: diameter stem base for woody and percent cover for herbaceous. Joint results are in percentaje cover | V19: no | W19: fixed plots/quadrats | X19: 1 | Y19: NA | Z19: 1 | AA19: 71 | AB19: 1 | AC19: deforestation and reforestation phases. 4.4% remaining forest cover | AD19: NA | AE19: intensive maize crop | AF19: bought for passive restoration | AG19: 1 | AH19: NA | AI19: Plots are aggregated but we do not know how | AJ19: NA | AK19: Belgium | AL19: vascular plants | AM19: mix | AN19: cultivation | AO19: protection | AP19: NA | AQ19: NA | AR19: none | AS19: 0 | AT19: 1 | AU19: none | AV19: protection | AW19: community | AX19: species | AY19: 92 | AZ19: 14 | BA19: 45.97 | BB19: 2.3577913e+16 | BC19: 648844491 | BD19: 9 | BE19: 0.13043478260869565
A20: PR_Baeten et al. 2010_Baeten Belgium vegetation recovery_p26_NA | B20: PR | C20: Baeten et al. 2010_Baeten Belgium vegetation recovery_p26_NA | D20: PR_Baeten et al. 2010_Baeten Belgium vegetation recovery | E20: PR_Baeten et al. 2010_Baeten Belgium vegetation recovery | F20: Baeten et al. 2010 | G20: Baeten Belgium vegetation recovery | H20: p26 | I20: NA | J20: p26 | K20: 51115439 | L20: 3242017 | M20: 3 | N20: 3 | O20: 2006 | P20: exact | Q20: recovering | R20: woody and herbaceous | S20: presence | T20: abundance | U20: diameter stem base for woody and percent cover for herbaceous. Joint results are in percentaje cover | V20: no | W20: fixed plots/quadrats | X20: 1 | Y20: NA | Z20: 1 | AA20: 71 | AB20: 1 | AC20: deforestation and reforestation phases. 4.4% remaining forest cover | AD20: NA | AE20: intensive maize crop | AF20: bought for passive restoration | AG20: 1 | AH20: NA | AI20: Plots are aggregated but we do not know how | AJ20: NA | AK20: Belgium | AL20: vascular plants | AM20: mix | AN20: cultivation | AO20: protection | AP20: NA | AQ20: NA | AR20: none | AS20: 0 | AT20: 1 | AU20: none | AV20: protection | AW20: community | AX20: species | AY20: 92 | AZ20: 12 | BA20: 75.02 | BB20: 2.7060826e+16 | BC20: 675283187 | BD20: 10 | BE20: 0.13043478260869565
A21: PR_Baeten et al. 2010_Baeten Belgium vegetation recovery_p27_NA | B21: PR | C21: Baeten et al. 2010_Baeten Belgium vegetation recovery_p27_NA | D21: PR_Baeten et al. 2010_Baeten Belgium vegetation recovery | E21: PR_Baeten et al. 2010_Baeten Belgium vegetation recovery | F21: Baeten et al. 2010 | G21: Baeten Belgium vegetation recovery | H21: p27 | I21: NA | J21: p27 | K21: 51115287 | L21: 3241659 | M21: 3 | N21: 3 | O21: 2006 | P21: exact | Q21: recovering | R21: woody and herbaceous | S21: presence | T21: abundance | U21: diameter stem base for woody and percent cover for herbaceous. Joint results are in percentaje cover | V21: no | W21: fixed plots/quadrats | X21: 1 | Y21: NA | Z21: 1 | AA21: 71 | AB21: 1 | AC21: deforestation and reforestation phases. 4.4% remaining forest cover | AD21: NA | AE21: intensive maize crop | AF21: bought for passive restoration | AG21: 1 | AH21: NA | AI21: Plots are aggregated but we do not know how | AJ21: NA | AK21: Belgium | AL21: vascular plants | AM21: mix | AN21: cultivation | AO21: protection | AP21: NA | AQ21: NA | AR21: none | AS21: 0 | AT21: 1 | AU21: none | AV21: protection | AW21: community | AX21: species | AY21: 92 | AZ21: 17 | BA21: 46.87 | BB21: 3.0873053e+15 | BC21: 813508484 | BD21: 13 | BE21: 0.13043478260869565
A22: PR_Baeten et al. 2010_Baeten Belgium vegetation recovery_p28_NA | B22: PR | C22: Baeten et al. 2010_Baeten Belgium vegetation recovery_p28_NA | D22: PR_Baeten et al. 2010_Baeten Belgium vegetation recovery | E22: PR_Baeten et al. 2010_Baeten Belgium vegetation recovery | F22: Baeten et al. 2010 | G22: Baeten Belgium vegetation recovery | H22: p28 | I22: NA | J22: p28 | K22: 51115179 | L22: 3241344 | M22: 3 | N22: 3 | O22: 2006 | P22: exact | Q22: recovering | R22: woody and herbaceous | S22: presence | T22: abundance | U22: diameter stem base for woody and percent cover for herbaceous. Joint results are in percentaje cover | V22: no | W22: fixed plots/quadrats | X22: 1 | Y22: NA | Z22: 1 | AA22: 71 | AB22: 1 | AC22: deforestation and reforestation phases. 4.4% remaining forest cover | AD22: NA | AE22: intensive maize crop | AF22: bought for passive restoration | AG22: 1 | AH22: NA | AI22: Plots are aggregated but we do not know how | AJ22: NA | AK22: Belgium | AL22: vascular plants | AM22: mix | AN22: cultivation | AO22: protection | AP22: NA | AQ22: NA | AR22: none | AS22: 0 | AT22: 1 | AU22: none | AV22: protection | AW22: community | AX22: species | AY22: 92 | AZ22: 19 | BA22: 74.72 | BB22: 1.6942634e+15 | BC22: 936334162 | BD22: 13 | BE22: 0.13043478260869565
A23: PR_Baeten et al. 2010_Baeten Belgium vegetation recovery_p29_NA | B23: PR | C23: Baeten et al. 2010_Baeten Belgium vegetation recovery_p29_NA | D23: PR_Baeten et al. 2010_Baeten Belgium vegetation recovery | E23: PR_Baeten et al. 2010_Baeten Belgium vegetation recovery | F23: Baeten et al. 2010 | G23: Baeten Belgium vegetation recovery | H23: p29 | I23: NA | J23: p29 | K23: 51112365 | L23: 3245458 | M23: 1 | N23: 1 | O23: 2006 | P23: exact | Q23: recovering | R23: woody and herbaceous | S23: presence | T23: abundance | U23: diameter stem base for woody and percent cover for herbaceous. Joint results are in percentaje cover | V23: no | W23: fixed plots/quadrats | X23: 1 | Y23: NA | Z23: 1 | AA23: 71 | AB23: 1 | AC23: deforestation and reforestation phases. 4.4% remaining forest cover | AD23: NA | AE23: productive grassland | AF23: bought for passive restoration | AG23: 1 | AH23: NA | AI23: Plots are aggregated but we do not know how | AJ23: NA | AK23: Belgium | AL23: vascular plants | AM23: mix | AN23: animal farming | AO23: protection | AP23: NA | AQ23: NA | AR23: none | AS23: 0 | AT23: 1 | AU23: none | AV23: protection | AW23: community | AX23: species | AY23: 92 | AZ23: 16 | BA23: 44.92 | BB23: 1.3798559e+15 | BC23: 10451213648 | BD23: 14 | BE23: 0.13043478260869565
A24: PR_Baeten et al. 2010_Baeten Belgium vegetation recovery_p3_NA | B24: PR | C24: Baeten et al. 2010_Baeten Belgium vegetation recovery_p3_NA | D24: PR_Baeten et al. 2010_Baeten Belgium vegetation recovery | E24: PR_Baeten et al. 2010_Baeten Belgium vegetation recovery | F24: Baeten et al. 2010 | G24: Baeten Belgium vegetation recovery | H24: p3 | I24: NA | J24: p3 | K24: 51123056 | L24: 3223581 | M24: 2 | N24: 2 | O24: 2006 | P24: exact | Q24: recovering | R24: woody and herbaceous | S24: presence | T24: abundance | U24: diameter stem base for woody and percent cover for herbaceous. Joint results are in percentaje cover | V24: no | W24: fixed plots/quadrats | X24: 1 | Y24: NA | Z24: 1 | AA24: 71 | AB24: 1 | AC24: deforestation and reforestation phases. 4.4% remaining forest cover | AD24: NA | AE24: productive grassland | AF24: bought for passive restoration | AG24: 1 | AH24: NA | AI24: Plots are aggregated but we do not know how | AJ24: NA | AK24: Belgium | AL24: vascular plants | AM24: mix | AN24: animal farming | AO24: protection | AP24: NA | AQ24: NA | AR24: none | AS24: 0 | AT24: 1 | AU24: none | AV24: protection | AW24: community | AX24: species | AY24: 92 | AZ24: 14 | BA24: 44.14 | BB24: 2.9696016e+15 | BC24: 742332007 | BD24: 11 | BE24: 0.13043478260869565
... A27: PR_Baeten et al. 2010_Baeten Belgium vegetation recovery_p32_NA | B27: PR | C27: Baeten et al. 2010_Baeten Belgium vegetation recovery_p32_NA | D27: PR_Baeten et al. 2010_Baeten Belgium vegetation recovery | E27: PR_Baeten et al. 2010_Baeten Belgium vegetation recovery | F27: Baeten et al. 2010 | G27: Baeten Belgium vegetation recovery | H27: p32 | I27: NA | J27: p32 | K27: 5111189 | L27: 3244784 | M27: 1 | N27: 1 | O27: 2006 | P27: exact | Q27: recovering | R27: woody and herbaceous | S27: presence | T27: abundance | U27: diameter stem base for woody and percent cover for herbaceous. Joint results are in percentaje cover | V27: no | W27: fixed plots/quadrats | X27: 1 | Y27: NA | Z27: 1 | AA27: 71 | AB27: 1 | AC27: deforestation and reforestation phases. 4.4% remaining forest cover | AD27: NA | AE27: productive grassland | AF27: bought for passive restoration | AG27: 1 | AH27: NA | AI27: Plots are aggregated but we do not know how | AJ27: NA | AK27: Belgium | AL27: vascular plants | AM27: mix | AN27: animal farming | AO27: protection | AP27: NA | AQ27: NA | AR27: none | AS27: 0 | AT27: 1 | AU27: none | AV27: protection | AW27: community | AX27: species | AY27: 92 | AZ27: 14 | BA27: 76.28 | BB27: 2.3699292e+15 | BC27: 8.5911634e+15 | BD27: 10 | BE27: 0.13043478260869565
A28: PR_Baeten et al. 2010_Baeten Belgium vegetation recovery_p33_NA | B28: PR | C28: Baeten et al. 2010_Baeten Belgium vegetation recovery_p33_NA | D28: PR_Baeten et al. 2010_Baeten Belgium vegetation recovery | E28: PR_Baeten et al. 2010_Baeten Belgium vegetation recovery | F28: Baeten et al. 2010 | G28: Baeten Belgium vegetation recovery | H28: p33 | I28: NA | J28: p33 | K28: 51111756 | L28: 3244426 | M28: 1 | N28: 1 | O28: 2006 | P28: exact | Q28: recovering | R28: woody and herbaceous | S28: presence | T28: abundance | U28: diameter stem base for woody and percent cover for herbaceous. Joint results are in percentaje cover | V28: no | W28: fixed plots/quadrats | X28: 1 | Y28: NA | Z28: 1 | AA28: 71 | AB28: 1 | AC28: deforestation and reforestation phases. 4.4% remaining forest cover | AD28: NA | AE28: productive grassland | AF28: bought for passive restoration | AG28: 1 | AH28: NA | AI28: Plots are aggregated but we do not know how | AJ28: NA | AK28: Belgium | AL28: vascular plants | AM28: mix | AN28: animal farming | AO28: protection | AP28: NA | AQ28: NA | AR28: none | AS28: 0 | AT28: 1 | AU28: none | AV28: protection | AW28: community | AX28: species | AY28: 92 | AZ28: 9 | BA28: 100 | BB28: 1.2159205e+16 | BC28: 83438771 | BD28: 9 | BE28: 0.13043478260869565
A29: PR_Baeten et al. 2010_Baeten Belgium vegetation recovery_p34_NA | B29: PR | C29: Baeten et al. 2010_Baeten Belgium vegetation recovery_p34_NA | D29: PR_Baeten et al. 2010_Baeten Belgium vegetation recovery | E29: PR_Baeten et al. 2010_Baeten Belgium vegetation recovery | F29: Baeten et al. 2010 | G29: Baeten Belgium vegetation recovery | H29: p34 | I29: NA | J29: p34 | K29: 51111683 | L29: 3245011 | M29: 1 | N29: 1 | O29: 2006 | P29: exact | Q29: recovering | R29: woody and herbaceous | S29: presence | T29: abundance | U29: diameter stem base for woody and percent cover for herbaceous. Joint results are in percentaje cover | V29: no | W29: fixed plots/quadrats | X29: 1 | Y29: NA | Z29: 1 | AA29: 71 | AB29: 1 | AC29: deforestation and reforestation phases. 4.4% remaining forest cover | AD29: NA | AE29: productive grassland | AF29: bought for passive restoration | AG29: 1 | AH29: NA | AI29: Plots are aggregated but we do not know how | AJ29: NA | AK29: Belgium | AL29: vascular plants | AM29: mix | AN29: animal farming | AO29: protection | AP29: NA | AQ29: NA | AR29: none | AS29: 0 | AT29: 1 | AU29: none | AV29: protection | AW29: community | AX29: species | AY29: 92 | AZ29: 10 | BA29: 100 | BB29: 2.1334696e+15 | BC29: 763083031 | BD29: 9 | BE29: 0.13043478260869565
A30: PR_Baeten et al. 2010_Baeten Belgium vegetation recovery_p35_NA | B30: PR | C30: Baeten et al. 2010_Baeten Belgium vegetation recovery_p35_NA | D30: PR_Baeten et al. 2010_Baeten Belgium vegetation recovery | E30: PR_Baeten et al. 2010_Baeten Belgium vegetation recovery | F30: Baeten et al. 2010 | G30: Baeten Belgium vegetation recovery | H30: p35 | I30: NA | J30: p35 | K30: 51111531 | L30: 3244725 | M30: 1 | N30: 1 | O30: 2006 | P30: exact | Q30: recovering | R30: woody and herbaceous | S30: presence | T30: abundance | U30: diameter stem base for woody and percent cover for herbaceous. Joint results are in percentaje cover | V30: no | W30: fixed plots/quadrats | X30: 1 | Y30: NA | Z30: 1 | AA30: 71 | AB30: 1 | AC30: deforestation and reforestation phases. 4.4% remaining forest cover | AD30: NA | AE30: productive grassland | AF30: bought for passive restoration | AG30: 1 | AH30: NA | AI30: Plots are aggregated but we do not know how | AJ30: NA | AK30: Belgium | AL30: vascular plants | AM30: mix | AN30: animal farming | AO30: protection | AP30: NA | AQ30: NA | AR30: none | AS30: 0 | AT30: 1 | AU30: none | AV30: protection | AW30: community | AX30: species | AY30: 92 | AZ30: 9 | BA30: 100 | BB30: 2.060498e+16 | BC30: 710653155 | BD30: 8 | BE30: 0.13043478260869565
A31: PR_Baeten et al. 2010_Baeten Belgium vegetation recovery_p36_NA | B31: PR | C31: Baeten et al. 2010_Baeten Belgium vegetation recovery_p36_NA | D31: PR_Baeten et al. 2010_Baeten Belgium vegetation recovery | E31: PR_Baeten et al. 2010_Baeten Belgium vegetation recovery | F31: Baeten et al. 2010 | G31: Baeten Belgium vegetation recovery | H31: p36 | I31: NA | J31: p36 | K31: 51111205 | L31: 324568 | M31: 1 | N31: 1 | O31: 2006 | P31: exact | Q31: recovering | R31: woody and herbaceous | S31: presence | T31: abundance | U31: diameter stem base for woody and percent cover for herbaceous. Joint results are in percentaje cover | V31: no | W31: fixed plots/quadrats | X31: 1 | Y31: NA | Z31: 1 | AA31: 71 | AB31: 1 | AC31: deforestation and reforestation phases. 4.4% remaining forest cover | AD31: NA | AE31: productive grassland | AF31: bought for passive restoration | AG31: 1 | AH31: NA | AI31: Plots are aggregated but we do not know how | AJ31: NA | AK31: Belgium | AL31: vascular plants | AM31: mix | AN31: animal farming | AO31: protection | AP31: NA | AQ31: NA | AR31: none | AS31: 0 | AT31: 1 | AU31: none | AV31: protection | AW31: community | AX31: species | AY31: 92 | AZ31: 14 | BA31: 63.13 | BB31: 2.3421327e+15 | BC31: 784891812 | BD31: 11 | BE31: 0.13043478260869565
A32: PR_Baeten et al. 2010_Baeten Belgium vegetation recovery_p37_NA | B32: PR | C32: Baeten et al. 2010_Baeten Belgium vegetation recovery_p37_NA | D32: PR_Baeten et al. 2010_Baeten Belgium vegetation recovery | E32: PR_Baeten et al. 2010_Baeten Belgium vegetation recovery | F32: Baeten et al. 2010 | G32: Baeten Belgium vegetation recovery | H32: p37 | I32: NA | J32: p37 | K32: 5111108 | L32: 3245322 | M32: 1 | N32: 1 | O32: 2006 | P32: exact | Q32: recovering | R32: woody and herbaceous | S32: presence | T32: abundance | U32: diameter stem base for woody and percent cover for herbaceous. Joint results are in percentaje cover | V32: no | W32: fixed plots/quadrats | X32: 1 | Y32: NA | Z32: 1 | AA32: 71 | AB32: 1 | AC32: deforestation and reforestation phases. 4.4% remaining forest cover | AD32: NA | AE32: productive grassland | AF32: bought for passive restoration | AG32: 1 | AH32: NA | AI32: Plots are aggregated but we do not know how | AJ32: NA | AK32: Belgium | AL32: vascular plants | AM32: mix | AN32: animal farming | AO32: protection | AP32: NA | AQ32: NA | AR32: none | AS32: 0 | AT32: 1 | AU32: none | AV32: protection | AW32: community | AX32: species | AY32: 92 | AZ32: 16 | BA32: 59.13 | BB32: 2.4797169e+15 | BC32: 1018059253 | BD32: 14 | BE32: 0.13043478260869565
A33: PR_Baeten et al. 2010_Baeten Belgium vegetation recovery_p38_NA | B33: PR | C33: Baeten et al. 2010_Baeten Belgium vegetation recovery_p38_NA | D33: PR_Baeten et al. 2010_Baeten Belgium vegetation recovery | E33: PR_Baeten et al. 2010_Baeten Belgium vegetation recovery | F33: Baeten et al. 2010 | G33: Baeten Belgium vegetation recovery | H33: p38 | I33: NA | J33: p38 | K33: 5111932 | L33: 3248138 | M33: 4 | N33: 4 | O33: 2006 | P33: exact | Q33: recovering | R33: woody and herbaceous | S33: presence | T33: abundance | U33: diameter stem base for woody and percent cover for herbaceous. Joint results are in percentaje cover | V33: no | W33: fixed plots/quadrats | X33: 1 | Y33: NA | Z33: 1 | AA33: 71 | AB33: 1 | AC33: deforestation and reforestation phases. 4.4% remaining forest cover | AD33: NA | AE33: intensive maize crop | AF33: bought for passive restoration | AG33: 1 | AH33: NA | AI33: Plots are aggregated but we do not know how | AJ33: NA | AK33: Belgium | AL33: vascular plants | AM33: mix | AN33: cultivation | AO33: protection | AP33: NA | AQ33: NA | AR33: none | AS33: 0 | AT33: 1 | AU33: none | AV33: protection | AW33: community | AX33: species | AY33: 92 | AZ33: 16 | BA33: 94 | BB33: 2.5586812e+16 | BC33: 1051556426 | BD33: 13 | BE33: 0.13043478260869565
A34: PR_Baeten et al. 2010_Baeten Belgium vegetation recovery_p39_NA | B34: PR | C34: Baeten et al. 2010_Baeten Belgium vegetation recovery_p39_NA | D34: PR_Baeten et al. 2010_Baeten Belgium vegetation recovery | E34: PR_Baeten et al. 2010_Baeten Belgium vegetation recovery | F34: Baeten et al. 2010 | G34: Baeten Belgium vegetation recovery | H34: p39 | I34: NA | J34: p39 | K34: 5111913 | L34: 3248423 | M34: 4 | N34: 4 | O34: 2006 | P34: exact | Q34: recovering | R34: woody and herbaceous | S34: presence | T34: abundance | U34: diameter stem base for woody and percent cover for herbaceous. Joint results are in percentaje cover | V34: no | W34: fixed plots/quadrats | X34: 1 | Y34: NA | Z34: 1 | AA34: 71 | AB34: 1 | AC34: deforestation and reforestation phases. 4.4% remaining forest cover | AD34: NA | AE34: intensive maize crop | AF34: bought for passive restoration | AG34: 1 | AH34: NA | AI34: Plots are aggregated but we do not know how | AJ34: NA | AK34: Belgium | AL34: vascular plants | AM34: mix | AN34: cultivation | AO34: protection | AP34: NA | AQ34: NA | AR34: none | AS34: 0 | AT34: 1 | AU34: none | AV34: protection | AW34: community | AX34: species | AY34: 92 | AZ34: 12 | BA34: 98.02 | BB34: 1.0099246e+15 | BC34: 788431386 | BD34: 10 | BE34: 0.13043478260869565
A35: PR_Baeten et al. 2010_Baeten Belgium vegetation recovery_p4_NA | B35: PR | C35: Baeten et al. 2010_Baeten Belgium vegetation recovery_p4_NA | D35: PR_Baeten et al. 2010_Baeten Belgium vegetation recovery | E35: PR_Baeten et al. 2010_Baeten Belgium vegetation recovery | F35: Baeten et al. 2010 | G35: Baeten Belgium vegetation recovery | H35: p4 | I35: NA | J35: p4 | K35: 5112396 | L35: 32258 | M35: 4 | N35: 4 | O35: 2006 | P35: exact | Q35: recovering | R35: woody and herbaceous | S35: presence | T35: abundance | U35: diameter stem base for woody and percent cover for herbaceous. Joint results are in percentaje cover | V35: no | W35: fixed plots/quadrats | X35: 1 | Y35: NA | Z35: 1 | AA35: 71 | AB35: 1 | AC35: deforestation and reforestation phases. 4.4% remaining forest cover | AD35: NA | AE35: intensive maize crop | AF35: bought for passive restoration | AG35: 1 | AH35: NA | AI35: Plots are aggregated but we do not know how | AJ35: NA | AK35: Belgium | AL35: vascular plants | AM35: mix | AN35: cultivation | AO35: protection | AP35: NA | AQ35: NA | AR35: none | AS35: 0 | AT35: 1 | AU35: none | AV35: protection | AW35: community | AX35: species | AY35: 92 | AZ35: 11 | BA35: 93.83 | BB35: 1.5860923e+15 | BC35: 69654502 | BD35: 9 | BE35: 0.13043478260869565
A36: PR_Baeten et al. 2010_Baeten Belgium vegetation recovery_p40_NA | B36: PR | C36: Baeten et al. 2010_Baeten Belgium vegetation recovery_p40_NA | D36: PR_Baeten et al. 2010_Baeten Belgium vegetation recovery | E36: PR_Baeten et al. 2010_Baeten Belgium vegetation recovery | F36: Baeten et al. 2010 | G36: Baeten Belgium vegetation recovery | H36: p40 | I36: NA | J36: p40 | K36: 51118941 | L36: 3248622 | M36: 4 | N36: 4 | O36: 2006 | P36: exact | Q36: recovering | R36: woody and herbaceous | S36: presence | T36: abundance | U36: diameter stem base for woody and percent cover for herbaceous. Joint results are in percentaje cover | V36: no | W36: fixed plots/quadrats | X36: 1 | Y36: NA | Z36: 1 | AA36: 71 | AB36: 1 | AC36: deforestation and reforestation phases. 4.4% remaining forest cover | AD36: NA | AE36: intensive maize crop | AF36: bought for passive restoration | AG36: 1 | AH36: NA | AI36: Plots are aggregated but we do not know how | AJ36: NA | AK36: Belgium | AL36: vascular plants | AM36: mix | AN36: cultivation | AO36: protection | AP36: NA | AQ36: NA | AR36: none | AS36: 0 | AT36: 1 | AU36: none | AV36: protection | AW36: community | AX36: species | AY36: 92 | AZ36: 7 | BA36: 97.97 | BB36: 1.0036926e+16 | BC36: 554027153 | BD36: 6 | BE36: 0.13043478260869565
A37: PR_Baeten et al. 2010_Baeten Belgium vegetation recovery_p41_NA | B37: PR | C37: Baeten et al. 2010_Baeten Belgium vegetation recovery_p41_NA | D37: PR_Baeten et al. 2010_Baeten Belgium vegetation recovery | E37: PR_Baeten et al. 2010_Baeten Belgium vegetation recovery | F37: Baeten et al. 2010 | G37: Baeten Belgium vegetation recovery | H37: p41 | I37: NA | J37: p41 | K37: 51118752 | L37: 3248849 | M37: 4 | N37: 4 | O37: 2006 | P37: exact | Q37: recovering | R37: woody and herbaceous | S37: presence | T37: abundance | U37: diameter stem base for woody and percent cover for herbaceous. Joint results are in percentaje cover | V37: no | W37: fixed plots/quadrats | X37: 1 | Y37: NA | Z37: 1 | AA37: 71 | AB37: 1 | AC37: deforestation and reforestation phases. 4.4% remaining forest cover | AD37: NA | AE37: intensive maize crop | AF37: bought for passive restoration | AG37: 1 | AH37: NA | AI37: Plots are aggregated but we do not know how | AJ37: NA | AK37: Belgium | AL37: vascular plants | AM37: mix | AN37: cultivation | AO37: protection | AP37: NA | AQ37: NA | AR37: none | AS37: 0 | AT37: 1 | AU37: none | AV37: protection | AW37: community | AX37: species | AY37: 92 | AZ37: 15 | BA37: 97.13 | BB37: 2.4210744e+16 | BC37: 1064134065 | BD37: 13 | BE37: 0.13043478260869565
A38: PR_Baeten et al. 2010_Baeten Belgium vegetation recovery_p42_NA | B38: PR | C38: Baeten et al. 2010_Baeten Belgium vegetation recovery_p42_NA | D38: PR_Baeten et al. 2010_Baeten Belgium vegetation recovery | E38: PR_Baeten et al. 2010_Baeten Belgium vegetation recovery | F38: Baeten et al. 2010 | G38: Baeten Belgium vegetation recovery | H38: p42 | I38: NA | J38: p42 | K38: 51119436 | L38: 3248467 | M38: 4 | N38: 4 | O38: 2006 | P38: exact | Q38: recovering | R38: woody and herbaceous | S38: presence | T38: abundance | U38: diameter stem base for woody and percent cover for herbaceous. Joint results are in percentaje cover | V38: no | W38: fixed plots/quadrats | X38: 1 | Y38: NA | Z38: 1 | AA38: 71 | AB38: 1 | AC38: deforestation and reforestation phases. 4.4% remaining forest cover | AD38: NA | AE38: intensive maize crop | AF38: bought for passive restoration | AG38: 1 | AH38: NA | AI38: Plots are aggregated but we do not know how | AJ38: NA | AK38: Belgium | AL38: vascular plants | AM38: mix | AN38: cultivation | AO38: protection | AP38: NA | AQ38: NA | AR38: none | AS38: 0 | AT38: 1 | AU38: none | AV38: protection | AW38: community | AX38: species | AY38: 92 | AZ38: 15 | BA38: 100.01 | BB38: 1.9631518e+16 | BC38: 835607748 | BD38: 12 | BE38: 0.13043478260869565
A39: PR_Baeten et al. 2010_Baeten Belgium vegetation recovery_p43_NA | B39: PR | C39: Baeten et al. 2010_Baeten Belgium vegetation recovery_p43_NA | D39: PR_Baeten et al. 2010_Baeten Belgium vegetation recovery | E39: PR_Baeten et al. 2010_Baeten Belgium vegetation recovery | F39: Baeten et al. 2010 | G39: Baeten Belgium vegetation recovery | H39: p43 | I39: NA | J39: p43 | K39: 51119247 | L39: 3248666 | M39: 4 | N39: 4 | O39: 2006 | P39: exact | Q39: recovering | R39: woody and herbaceous | S39: presence | T39: abundance | U39: diameter stem base for woody and percent cover for herbaceous. Joint results are in percentaje cover | V39: no | W39: fixed plots/quadrats | X39: 1 | Y39: NA | Z39: 1 | AA39: 71 | AB39: 1 | AC39: deforestation and reforestation phases. 4.4% remaining forest cover | AD39: NA | AE39: intensive maize crop | AF39: bought for passive restoration | AG39: 1 | AH39: NA | AI39: Plots are aggregated but we do not know how | AJ39: NA | AK39: Belgium | AL39: vascular plants | AM39: mix | AN39: cultivation | AO39: protection | AP39: NA | AQ39: NA | AR39: none | AS39: 0 | AT39: 1 | AU39: none | AV39: protection | AW39: community | AX39: species | AY39: 92 | AZ39: 17 | BA39: 28.75 | BB39: 2.6357697e+16 | BC39: 885424665 | BD39: 13 | BE39: 0.13043478260869565
A40: PR_Baeten et al. 2010_Baeten Belgium vegetation recovery_p44_NA | B40: PR | C40: Baeten et al. 2010_Baeten Belgium vegetation recovery_p44_NA | D40: PR_Baeten et al. 2010_Baeten Belgium vegetation recovery | E40: PR_Baeten et al. 2010_Baeten Belgium vegetation recovery | F40: Baeten et al. 2010 | G40: Baeten Belgium vegetation recovery | H40: p44 | I40: NA | J40: p44 | K40: 51119057 | L40: 3248894 | M40: 4 | N40: 4 | O40: 2006 | P40: exact | Q40: recovering | R40: woody and herbaceous | S40: presence | T40: abundance | U40: diameter stem base for woody and percent cover for herbaceous. Joint results are in percentaje cover | V40: no | W40: fixed plots/quadrats | X40: 1 | Y40: NA | Z40: 1 | AA40: 71 | AB40: 1 | AC40: deforestation and reforestation phases. 4.4% remaining forest cover | AD40: NA | AE40: intensive maize crop | AF40: bought for passive restoration | AG40: 1 | AH40: NA | AI40: Plots are aggregated but we do not know how | AJ40: NA | AK40: Belgium | AL40: vascular plants | AM40: mix | AN40: cultivation | AO40: protection | AP40: NA | AQ40: NA | AR40: none | AS40: 0 | AT40: 1 | AU40: none | AV40: protection | AW40: community | AX40: species | AY40: 92 | AZ40: 14 | BA40: 6.196e+16 | BB40: 2.0856864e+16 | BC40: 747903653 | BD40: 12 | BE40: 0.13043478260869565
A41: PR_Baeten et al. 2010_Baeten Belgium vegetation recovery_p45_NA | B41: PR | C41: Baeten et al. 2010_Baeten Belgium vegetation recovery_p45_NA | D41: PR_Baeten et al. 2010_Baeten Belgium vegetation recovery | E41: PR_Baeten et al. 2010_Baeten Belgium vegetation recovery | F41: Baeten et al. 2010 | G41: Baeten Belgium vegetation recovery | H41: p45 | I41: NA | J41: p45 | K41: 51118868 | L41: 3249179 | M41: 4 | N41: 4 | O41: 2006 | P41: exact | Q41: recovering | R41: woody and herbaceous | S41: presence | T41: abundance | U41: diameter stem base for woody and percent cover for herbaceous. Joint results are in percentaje cover | V41: no | W41: fixed plots/quadrats | X41: 1 | Y41: NA | Z41: 1 | AA41: 71 | AB41: 1 | AC41: deforestation and reforestation phases. 4.4% remaining forest cover | AD41: NA | AE41: intensive maize crop | AF41: bought for passive restoration | AG41: 1 | AH41: NA | AI41: Plots are aggregated but we do not know how | AJ41: NA | AK41: Belgium | AL41: vascular plants | AM41: mix | AN41: cultivation | AO41: protection | AP41: NA | AQ41: NA | AR41: none | AS41: 0 | AT41: 1 | AU41: none | AV41: protection | AW41: community | AX41: species | AY41: 92 | AZ41: 9 | BA41: 91.02 | BB41: 0.9614489100033112 | BC41: 57636734 | BD41: 8 | BE41: 0.13043478260869565
A42: PR_Baeten et al. 2010_Baeten Belgium vegetation recovery_p46_NA | B42: PR | C42: Baeten et al. 2010_Baeten Belgium vegetation recovery_p46_NA | D42: PR_Baeten et al. 2010_Baeten Belgium vegetation recovery | E42: PR_Baeten et al. 2010_Baeten Belgium vegetation recovery | F42: Baeten et al. 2010 | G42: Baeten Belgium vegetation recovery | H42: p46 | I42: NA | J42: p46 | K42: 51119597 | L42: 3248782 | M42: 4 | N42: 4 | O42: 2006 | P42: exact | Q42: recovering | R42: woody and herbaceous | S42: presence | T42: abundance | U42: diameter stem base for woody and percent cover for herbaceous. Joint results are in percentaje cover | V42: no | W42: fixed plots/quadrats | X42: 1 | Y42: NA | Z42: 1 | AA42: 71 | AB42: 1 | AC42: deforestation and reforestation phases. 4.4% remaining forest cover | AD42: NA | AE42: intensive maize crop | AF42: bought for passive restoration | AG42: 1 | AH42: NA | AI42: Plots are aggregated but we do not know how | AJ42: NA | AK42: Belgium | AL42: vascular plants | AM42: mix | AN42: cultivation | AO42: protection | AP42: NA | AQ42: NA | AR42: none | AS42: 0 | AT42: 1 | AU42: none | AV42: protection | AW42: community | AX42: species | AY42: 92 | AZ42: 15 | BA42: 64.94 | BB42: 2.6495888e+16 | BC42: 740541462 | BD42: 12 | BE42: 0.13043478260869565
...

Sheet comm_nodist_plants1
D3: name | E3: type | F3: Description | G3: value1 | H3: value2 | I3: value3 | J3: value4 | K3: value5 | L3: value6 | M3: value7 | N3: value8 | O3: value9
D4: id | E4: character | F4: =VLOOKUP(D4,comm_nodist_plants2!C:D,2,FALSE) -> #N/A | G4: PR_Baeten et al. 2010_Baeten Belgium vegetation recovery_p1_NA | H4: PR_Baeten et al. 2010_Baeten Belgium vegetation recovery_p10_NA | I4: PR_Baeten et al. 2010_Baeten Belgium vegetation recovery_p11_NA | J4: PR_Baeten et al. 2010_Baeten Belgium vegetation recovery_p12_NA | K4: PR_Baeten et al. 2010_Baeten Belgium vegetation recovery_p13_NA | L4: PR_Baeten et al. 2010_Baeten Belgium vegetation recovery_p14_NA | M4: PR_Baeten et al. 2010_Baeten Belgium vegetation recovery_p15_NA | N4: PR_Baeten et al. 2010_Baeten Belgium vegetation recovery_p16_NA | O4: PR_Baeten et al. 2010_Baeten Belgium vegetation recovery_p17_NA
D5: database | E5: character | F5: =VLOOKUP(D5,comm_nodist_plants2!C:D,2,FALSE) -> #N/A | G5: PR | H5: PR | I5: PR | J5: PR | K5: PR | L5: PR | M5: PR | N5: PR | O5: PR
D6: id_comm | E6: character | F6: =VLOOKUP(D6,comm_nodist_plants2!C:D,2,FALSE) -> #N/A | G6: Baeten et al. 2010_Baeten Belgium vegetation recovery_p1_NA | H6: Baeten et al. 2010_Baeten Belgium vegetation recovery_p10_NA | I6: Baeten et al. 2010_Baeten Belgium vegetation recovery_p11_NA | J6: Baeten et al. 2010_Baeten Belgium vegetation recovery_p12_NA | K6: Baeten et al. 2010_Baeten Belgium vegetation recovery_p13_NA | L6: Baeten et al. 2010_Baeten Belgium vegetation recovery_p14_NA | M6: Baeten et al. 2010_Baeten Belgium vegetation recovery_p15_NA | N6: Baeten et al. 2010_Baeten Belgium vegetation recovery_p16_NA | O6: Baeten et al. 2010_Baeten Belgium vegetation recovery_p17_NA
D7: id_study | E7: character | F7: =VLOOKUP(D7,comm_nodist_plants2!C:D,2,FALSE) -> #N/A | G7: PR_Baeten et al. 2010_Baeten Belgium vegetation recovery | H7: PR_Baeten et al. 2010_Baeten Belgium vegetation recovery | I7: PR_Baeten et al. 2010_Baeten Belgium vegetation recovery | J7: PR_Baeten et al. 2010_Baeten Belgium vegetation recovery | K7: PR_Baeten et al. 2010_Baeten Belgium vegetation recovery | L7: PR_Baeten et al. 2010_Baeten Belgium vegetation recovery | M7: PR_Baeten et al. 2010_Baeten Belgium vegetation recovery | N7: PR_Baeten et al. 2010_Baeten Belgium vegetation recovery | O7: PR_Baeten et al. 2010_Baeten Belgium vegetation recovery
D8: id_study_ori | E8: character | F8: =VLOOKUP(D8,comm_nodist_plants2!C:D,2,FALSE) -> #N/A | G8: PR_Baeten et al. 2010_Baeten Belgium vegetation recovery | H8: PR_Baeten et al. 2010_Baeten Belgium vegetation recovery | I8: PR_Baeten et al. 2010_Baeten Belgium vegetation recovery | J8: PR_Baeten et al. 2010_Baeten Belgium vegetation recovery | K8: PR_Baeten et al. 2010_Baeten Belgium vegetation recovery | L8: PR_Baeten et al. 2010_Baeten Belgium vegetation recovery | M8: PR_Baeten et al. 2010_Baeten Belgium vegetation recovery | N8: PR_Baeten et al. 2010_Baeten Belgium vegetation recovery | O8: PR_Baeten et al. 2010_Baeten Belgium vegetation recovery
D9: citation | E9: character | F9: =VLOOKUP(D9,comm_nodist_plants2!C:D,2,FALSE) -> #N/A | G9: Baeten et al. 2010 | H9: Baeten et al. 2010 | I9: Baeten et al. 2010 | J9: Baeten et al. 2010 | K9: Baeten et al. 2010 | L9: Baeten et al. 2010 | M9: Baeten et al. 2010 | N9: Baeten et al. 2010 | O9: Baeten et al. 2010
D10: study | E10: character | F10: =VLOOKUP(D10,comm_nodist_plants2!C:D,2,FALSE) -> a study can be different from other because they consider different organisms within the same source (e.g. Purata 1986), different types of measurements in the same plots or different sampling methodologies. The differentiation by organism is made if the author explicitly did, but if not all organism types will be in the same study (e.g. Romero-Duque et al. 2007 includes all woody species independently if they are trees, shrubs, lianas, etc. and other studies are focused in one of these groups). Different disturbances do not differenciate studies if there is a common reference (e.g. Purata 1996). “Study” comprises all the assemblages that are comparable to the same reference or disturbed assemblage and contains different sites and plots. | G10: Baeten Belgium vegetation recovery | H10: Baeten Belgium vegetation recovery | I10: Baeten Belgium vegetation recovery | J10: Baeten Belgium vegetation recovery | K10: Baeten Belgium vegetation recovery | L10: Baeten Belgium vegetation recovery | M10: Baeten Belgium vegetation recovery | N10: Baeten Belgium vegetation recovery | O10: Baeten Belgium vegetation recovery
D11: site | E11: character | F11: =VLOOKUP(D11,comm_nodist_plants2!C:D,2,FALSE) -> sampling site. For spatially blocked designs where pseudo-replicate information is available, each site may contain different plots. | G11: p1 | H11: p10 | I11: p11 | J11: p12 | K11: p13 | L11: p14 | M11: p15 | N11: p16 | O11: p17
D12: plot | E12: character | F12: =VLOOKUP(D12,comm_nodist_plants2!C:D,2,FALSE) -> spatial or temporal pseudo-replicates | G12: NA | H12: NA | I12: NA | J12: NA | K12: NA | L12: NA | M12: NA | N12: NA | O12: NA
D13: id_comm_source | E13: character | F13: =VLOOKUP(D13,comm_nodist_plants2!C:D,2,FALSE) -> #N/A | G13: p1 | H13: p10 | I13: p11 | J13: p12 | K13: p13 | L13: p14 | M13: p15 | N13: p16 | O13: p17
D14: exact_lat | E14: double | F14: =VLOOKUP(D14,comm_nodist_plants2!C:D,2,FALSE) -> #N/A | G14: 51123051 | H14: 51119913 | I14: 51120067 | J14: 51120175 | K14: 51116535 | L14: 51116813 | M14: 51117118 | N14: 51116424 | O14: 51116353
D15: exact_long | E15: double | F15: =VLOOKUP(D15,comm_nodist_plants2!C:D,2,FALSE) -> #N/A | G15: 3221795 | H15: 3235139 | I15: 3234797 | J15: 3234512 | K15: 3242265 | L15: 3242824 | M15: 3243383 | N15: 3243893 | O15: 3243536
D16: age | E16: double | F16: =VLOOKUP(D16,comm_nodist_plants2!C:D,2,FALSE) -> a number with years since disturbance stopped. It is the mean if a range is given, the limit if an interval is given or 1 in “recent”. | G16: 2 | H16: 1 | I16: 1 | J16: 1 | K16: 5 | L16: 5 | M16: 5 | N16: 3 | O16: 3
D17: age_ori | E17: character | F17: =VLOOKUP(D17,comm_nodist_plants2!C:D,2,FALSE) -> #N/A | G17: 2 | H17: 1 | I17: 1 | J17: 1 | K17: 5 | L17: 5 | M17: 5 | N17: 3 | O17: 3
D18: study_year | E18: double | F18: =VLOOKUP(D18,comm_nodist_plants2!C:D,2,FALSE) -> #N/A | G18: 2006 | H18: 2006 | I18: 2006 | J18: 2006 | K18: 2006 | L18: 2006 | M18: 2006 | N18: 2006 | O18: 2006
D19: temp_persp_class2 | E19: character | F19: =VLOOKUP(D19,comm_nodist_plants2!C:D,2,FALSE) -> #N/A | G19: exact | H19: exact | I19: exact | J19: exact | K19: exact | L19: exact | M19: exact | N19: exact | O19: exact
D20: stage | E20: character | F20: =VLOOKUP(D20,comm_nodist_plants2!C:D,2,FALSE) -> is the community identified as a reference/old-growth/primary/mature forest (p.e. Dent 2013), or disturbed site in the original study? Mature and primary forests can be references even when a ongoing disturbance is identified. If not, then it is a recovering stage. Productive plantations can be considered as disturbed states if there is a clear management as a forest crop or recovering if they are abandoned or there is a clear objective to keep the forest. | G20: recovering | H20: recovering | I20: recovering | J20: recovering | K20: recovering | L20: recovering | M20: recovering | N20: recovering | O20: recovering
D21: study_common_taxon | E21: character | F21: =VLOOKUP(D21,comm_nodist_plants2!C:D,2,FALSE) -> #N/A | G21: woody and herbaceous | H21: woody and herbaceous | I21: woody and herbaceous | J21: woody and herbaceous | K21: woody and herbaceous | L21: woody and herbaceous | M21: woody and herbaceous | N21: woody and herbaceous | O21: woody and herbaceous
D22: organism_threshold | E22: character | F22: =VLOOKUP(D22,comm_nodist_plants2!C:D,2,FALSE) -> #N/A | G22: presence | H22: presence | I22: presence | J22: presence | K22: presence | L22: presence | M22: presence | N22: presence | O22: presence
D23: metric | E23: character | F23: =VLOOKUP(D23,comm_nodist_plants2!C:D,2,FALSE) -> #N/A | G23: abundance | H23: abundance | I23: abundance | J23: abundance | K23: abundance | L23: abundance | M23: abundance | N23: abundance | O23: abundance
